Workbook

Sheet HuongDan
A1: VBot – File báo giá chung của team (Lab28)
A2: Sheet nộp bài: BaoGia + BangChung. Sheet Sizing và HuongDan là sheet phụ, công cụ kiểm tra bỏ qua.
A4: QUY TRÌNH
A5: 1. Upload file lên Google Drive → mở bằng Google Sheets → share quyền sửa cho cả team.
A6: 2. B điền sheet Sizing trước (giả định + giá model). Các dòng llm, embedding, governance ở BaoGia tự lấy số từ Sizing; ở cột Bằng chứng các dòng đó ghi cùng mã ảnh đã dùng trong Sizing.
A7: 3. Mỗi người điền các dòng mang màu của mình ở BaoGia: cột Ghi chú (xem comment gợi ý ở từng ô), Chi phí, Bằng chứng.
A8: 4. Lấy giá xong → chụp ảnh NGAY (thấy tên dịch vụ, SKU, region, đơn giá) → dán vào sheet BangChung đúng dải mã của mình.
A9: 5. Cần thêm dòng: chèn dòng mới PHÍA TRÊN dòng TOTAL, chọn Component từ dropdown. Dòng TOTAL luôn ở cuối.
A10: 6. Tải về: Tệp › Tải xuống › Microsoft Excel (.xlsx) → kéo vào công cụ kiểm tra trong vbot-capstone.html → sửa đến khi ĐẠT.
A11: 7. Đổi tên G<mã nhóm>_baogia.xlsx. Tổng trên slide = dòng TOTAL.
A13: QUY TẮC (công cụ kiểm tra bắt lỗi)
A14: • KHÔNG viết các chữ: free tier, trial, free credit, miễn phí, dùng thử, khuyến mãi, startup credit – ở BaoGia, kể cả câu phủ định và trong link.
... A21: PHÂN CÔNG (điền tên)
A22: A – Lead + Cloud/HA | C22: Tên: | D22: Mã bằng chứng: E01–E29
A23: B – Model + AI governance | C23: Tên: | D23: Mã bằng chứng: E30–E59
A24: C – Data + Sandbox + Identity | C24: Tên: | D24: Mã bằng chứng: E60–E89
A26: HƯỚNG DẪN TỪNG COMPONENT (★ = bắt buộc trong đề)
A27: Component | B27: Người | C27: Đề yêu cầu ghi | D27: Cần quyết định / tính | E27: Gợi ý AWS | F27: Gợi ý Google Cloud | G27: Gợi ý Azure | H27: Đòn bẩy tiết kiệm
A28: compute ★ | B28: A | C28: Loại máy hoặc node, số lượng, autoscale theo giờ hành chính | D28: Số node app từ RPS cao điểm; prod 2 AZ; staging nhỏ | E28: EKS + EC2 | F28: GKE + Compute Engine | G28: AKS + VM | H28: Scale xuống ngoài giờ (220h); savings plan cho baseline; ARM (Graviton/Axion)
A29: load_balancer ★ | B29: A | C29: Loại LB, TLS, health check, đặt trước thành phần nào | D29: LB L7 multi-AZ trước gateway | E29: Application Load Balancer | F29: Cloud Load Balancing | G29: Application Gateway | H29: Dùng 1 LB cho nhiều service (path routing)
A30: network ★ | B30: A | C30: Subnet riêng, kiểm soát egress, WAF, private endpoint tới API model | D30: NAT mỗi AZ, private endpoint, WAF, egress GB | E30: NAT Gateway, PrivateLink, AWS WAF | F30: Cloud NAT, Private Service Connect, Cloud Armor | G30: NAT Gateway, Private Link, Azure WAF | H30: Gom egress qua ít NAT; endpoint chỉ cho dịch vụ cần
A31: backup_dr ★ | B31: A | C31: Lịch backup, nơi lưu, RTO và RPO, diễn tập khôi phục | D31: PITR DB (RPO 1h), copy cross-region, test restore hằng tháng | E31: AWS Backup, S3 cross-region | F31: Backup and DR, GCS dual-region | G31: Azure Backup, GRS | H31: Warm standby nhỏ hoặc chỉ backup (RTO 4h cho phép restore)
A32: monitoring ★ | B32: A | C32: Đo gì, cảnh báo gì, chi phí theo user và đơn vị | D32: GB log/tháng, audit 12 tháng, dashboard FinOps | E32: CloudWatch | F32: Cloud Logging + Monitoring | G32: Azure Monitor + Log Analytics | H32: Sampling log, chuyển audit sang object storage lạnh
A33: cicd ★ | B33: A | C33: Pipeline, registry, IaC, môi trường staging | D33: Pipeline, registry, Terraform, staging | E33: CodeBuild/GitHub Actions + ECR | F33: Cloud Build + Artifact Registry | G33: Azure DevOps + ACR | H33: Có thể "nằm trong" gói đang dùng
A34: ops_labor ★ | B34: A | C34: Số FTE, ca trực, phụ trách gì | D34: Bao nhiêu FTE cho 2.000 user, managed service giảm FTE | E34: — | F34: — | G34: — | H34: Dùng dịch vụ managed để giảm FTE; Bằng chứng ghi NA
A35: licenses | B35: A | C35: Gói support của cloud, license phần mềm | D35: Gói support | E35: AWS Business Support | F35: Google Cloud Enhanced Support | G35: Azure Standard Support | H35: Chọn gói vừa đủ SLA
A36: contingency | B36: A | C36: Vì sao cần, tính trên phần nào | D36: Có giữ không? (thêm tiền = giảm điểm) | E36: — | F36: — | G36: — | H36: Chỉ tính trên phần biến động (token)
A37: llm ★ | B37: B | C37: Model cho từng cấp tác vụ, API hay tự host, loại GPU, routing | D37: Model nhỏ/lớn, model tham chiếu H8, API vs tự host (hòa vốn) | E37: Bedrock | F37: Vertex AI | G37: Azure OpenAI / AI Foundry | H37: Route sang model nhỏ, prompt caching, batch cho agent nền
A38: embedding | B38: B | C38: Model embedding, chi phí index lần đầu và hằng ngày | D38: Model, token index, tần suất cập nhật | E38: Bedrock (Titan/Cohere Embed) | F38: Vertex AI text-embedding | G38: Azure OpenAI text-embedding-3 | H38: Chỉ embed lại phần thay đổi
... A49: secrets_kms ★ | B49: C | C49: Khóa mã hóa, nơi lưu secret và OAuth token, xoay khóa | D49: Số khóa, số secret, xoay khóa | E49: KMS + Secrets Manager | F49: Cloud KMS + Secret Manager | G49: Key Vault | H49: Gom token vào ít secret, mã hóa bằng 1 khóa/đơn vị
A51: Gợi ý dịch vụ chỉ để tham khảo: nhóm chọn 1 cloud chính (H1) và kiểm lại tên SKU + giá trên trang chính thức.

Sheet BaoGia
A1: Component | B1: Ý nghĩa | C1: Ghi chú | D1: Chi phí/tháng (USD) | E1: Bằng chứng
A2: compute | B2: Phí control plane cụm Kubernetes (prod + staging)
A3: compute | B3: Node pool ứng dụng prod: web, API, worker connector, LLM gateway
A4: compute | B4: Node pool staging (nhỏ, tắt ngoài giờ)
A5: load_balancer | B5: Load balancer HTTPS + TLS trước gateway (multi-AZ)
A6: network | B6: NAT gateway cho egress có kiểm soát (gọi API SaaS connectors)
A7: network | B7: Private endpoint tới API model và dịch vụ managed
A8: network | B8: WAF trước load balancer + egress ra internet
A9: backup_dr | B9: Backup DB + object storage sang region khác (RPO 1h, RTO 4h)
A10: monitoring | B10: Log, metric, trace + LLM observability (token theo user, đơn vị)
A11: monitoring | B11: Lưu audit log 12 tháng (H5)
A12: cicd | B12: CI/CD pipeline, container registry, IaC cho prod và staging
A13: ops_labor | B13: Kỹ sư SRE/Platform vận hành nền tảng | E13: NA
A14: licenses | B14: Gói support của cloud (bắt buộc với production)
A15: llm | B15: API model nhỏ cho cấp 1, 2, 5 (email, tài liệu, prompt thiết kế) | D15: =ROUND(Sizing!$B$41,2)
A16: llm | B16: API model lớn cho cấp 3, 4 (code, agent dự án) | D16: =ROUND(Sizing!$B$42,2)
A17: llm | B17: Sinh ảnh minh họa cho cấp 5 | D17: =ROUND(Sizing!$B$44,2)
A18: embedding | B18: Embedding tài liệu nội bộ và câu hỏi (index + cập nhật) | D18: =ROUND(Sizing!$B$66,2)
A19: gateway | B19: LLM gateway: routing model, quota theo người, rate limit, fallback, log token
A20: gateway | B20: API gateway cho backend (xác thực token, rate limit)
A21: governance | B21: Guardrail đầu vào/ra, chống prompt injection từ email và tài liệu | D21: =ROUND(Sizing!$B$51,2)
A22: governance | B22: DLP che PII + phân loại dữ liệu
A23: governance | B23: Eval gate trước khi đổi model hoặc prompt | D23: =ROUND(Sizing!$B$56,2)
A24: connectors | B24: Dịch vụ connector: Google Workspace, Microsoft Graph, Notion, Jira, Confluence (OAuth ủy nhiệm, webhook)
A25: database | B25: PostgreSQL HA multi-AZ: user, quyền, lịch sử chat, bộ nhớ dài hạn, metadata
A26: database | B26: Database staging (1 instance nhỏ)
A27: vector_db | B27: Vector index tài liệu, lọc kết quả theo ACL gốc và theo user
A28: object_storage | B28: Workspace riêng mỗi người (prefix + khóa riêng), file agent tạo ra, quota 10 GB
A29: cache_queue | B29: Redis managed HA: cache phiên, kết quả, rate limit
A30: cache_queue | B30: Hàng đợi tác vụ agent chạy nền (retry, hủy, thông báo)
A31: sandbox | B31: Node pool sandbox gVisor/microVM cho code của agent, không egress
A32: authn | B32: SSO tập đoàn (OIDC/SAML) + MFA
A33: authz | B33: Policy engine RBAC/ABAC + ACL tài liệu theo quyền gốc + scope OAuth
A34: secrets_kms | B34: KMS + token vault lưu OAuth token mã hóa, xoay khóa
A35: contingency | B35: Dự phòng biến động lượng token (10% chi phí LLM) | D35: =ROUND(0.1*(D15+D16+D17),2) | E35: NA
A36: TOTAL | D36: =SUM(D2:D35)

Sheet BangChung
A1: evidence_id | B1: Mô tả (dịch vụ, SKU, region, đơn giá) | C1: Link (trang giá / calculator đã lưu) | D1: Ngày chụp | E1: Ảnh chụp màn hình
A2: E01
A3: E02
A4: E03
A5: E04
A6: E05
A7: E06
A8: E07
A9: E08
A10: E09
A11: E10
A12: E30
A13: E31
... A31: E69

Sheet Sizing
A1: SIZING – từ 2.000 DAU ra token, lượt sandbox, dung lượng (ô vàng = nhóm sửa, ô xám = công thức)
A2: Mọi con số ở đây phải xuất hiện trên slide "Giả định và ước lượng tải". Ô vàng là giả định ban đầu để nhóm tranh luận, KHÔNG phải đáp án.
A4: 1. Đề cho
A5: Người dùng hoạt động mỗi ngày (DAU) | B5: 2000 | C5: người | D5: Đề cho
A6: Ngày làm việc mỗi tháng | B6: 22 | C6: ngày | D6: Đề cho
A7: Giờ hành chính mỗi ngày (8:00–18:00) | B7: 10 | C7: giờ | D7: Đề cho
A8: Giờ chạy 24/7 mỗi tháng | B8: 730 | C8: giờ | D8: Đề cho: dùng cho thành phần chạy liên tục (DB, LB…)
A9: Giờ hành chính mỗi tháng | B9: =$B$6*$B$7 | C9: giờ | D9: 22 × 10 = 220, dùng cho thành phần scale về 0 ngoài giờ
A11: 2. Tải tổng
A12: Request mỗi người mỗi ngày | B12: 25 | C12: request | D12: Gợi ý: file đề có hằng REQ_PER_USER = 25. Nhóm phải nêu căn cứ.
A13: Hệ số giờ cao điểm so với trung bình | B13: 3 | C13: lần | D13: Ví dụ 9–11h sáng gấp 3 lần trung bình
A14: Request mỗi tháng | B14: =$B$5*$B$12*$B$6 | C14: request | D14: DAU × request/ngày × 22
A15: Request/giây trung bình giờ hành chính | B15: =$B$5*$B$12/($B$7*3600) | C15: req/s
A16: Request/giây giờ cao điểm | B16: =$B$15*$B$13 | C16: req/s | D16: Dùng để sizing gateway, app node
A17: Tỉ lệ DAU online cùng lúc giờ cao điểm | B17: 0.3 | C17: % DAU
A18: Phiên đồng thời giờ cao điểm | B18: =$B$5*$B$17 | C18: phiên
A20: 3. Giá model (điền từ trang giá chính thức, ghi mã ảnh bằng chứng)
A21: Tỉ lệ token input trúng prompt cache | B21: 0.3 | C21: % | D21: Giả định tiết kiệm – hội đồng sẽ hỏi căn cứ
A22: Loại model | B22: Tên model / SKU | C22: Input USD/1M | D22: Input cached USD/1M | E22: Output USD/1M | F22: Mã bằng chứng | G22: Input hiệu dụng USD/1M
A23: Nhỏ | G23: =$B$21*D23+(1-$B$21)*C23
A24: Lớn | G24: =$B$21*D24+(1-$B$21)*C24
A25: Nhỏ = model rẻ cho cấp 1, 2, 5; Lớn = model mạnh cho cấp 3, 4. Đổi cột "Model" ở bảng 4 để thử routing.
A26: Giá sinh 1 ảnh | C26: USD/ảnh | D26: Cấp 5: dịch vụ sinh ảnh, ghi SKU + độ phân giải
A27: Số ảnh trung bình mỗi request cấp 5 | B27: 0.3 | C27: ảnh | D27: Không phải request thiết kế nào cũng sinh ảnh (sơ đồ, mockup có thể vẽ bằng code)
A28: Giá embedding | C28: USD/1M token
A30: 4. Năm cấp tác vụ
A31: Cấp tác vụ | B31: Tỉ lệ request | C31: Request/tháng | D31: Token vào/request | E31: Token ra/request | F31: Model | G31: Triệu token vào/tháng | H31: Triệu token ra/tháng | I31: USD input | J31: USD output | K31: USD tổng | L31: % chạy sandbox | M31: Lượt sandbox/tháng
A32: Cấp 1 – Email, hỏi đáp (RAG) | B32: 0.45 | C32: =$B$14*B32 | D32: 3000 | E32: 400 | F32: Nhỏ | G32: =C32*D32/1000000 | H32: =C32*E32/1000000 | I32: =G32*IF(F32="Nhỏ",$G$23,$G$24) | J32: =H32*IF(F32="Nhỏ",$E$23,$E$24) | K32: =I32+J32 | L32: 0 | M32: =C32*L32
A33: Cấp 2 – Tài liệu, slide (DOCX/XLSX/PPTX) | B33: 0.2 | C33: =$B$14*B33 | D33: 5000 | E33: 1500 | F33: Nhỏ | G33: =C33*D33/1000000 | H33: =C33*E33/1000000 | I33: =G33*IF(F33="Nhỏ",$G$23,$G$24) | J33: =H33*IF(F33="Nhỏ",$E$23,$E$24) | K33: =I33+J33 | L33: 0.3 | M33: =C33*L33
A34: Cấp 3 – Dữ liệu, code (sandbox) | B34: 0.15 | C34: =$B$14*B34 | D34: 8000 | E34: 1500 | F34: Lớn | G34: =C34*D34/1000000 | H34: =C34*E34/1000000 | I34: =G34*IF(F34="Nhỏ",$G$23,$G$24) | J34: =H34*IF(F34="Nhỏ",$E$23,$E$24) | K34: =I34+J34 | L34: 1 | M34: =C34*L34
A35: Cấp 4 – Agent dự án nhiều bước | B35: 0.12 | C35: =$B$14*B35 | D35: 25000 | E35: 3000 | F35: Lớn | G35: =C35*D35/1000000 | H35: =C35*E35/1000000 | I35: =G35*IF(F35="Nhỏ",$G$23,$G$24) | J35: =H35*IF(F35="Nhỏ",$E$23,$E$24) | K35: =I35+J35 | L35: 0.2 | M35: =C35*L35
A36: Cấp 5 – Thiết kế, ảnh minh họa | B36: 0.08 | C36: =$B$14*B36 | D36: 2000 | E36: 500 | F36: Nhỏ | G36: =C36*D36/1000000 | H36: =C36*E36/1000000 | I36: =G36*IF(F36="Nhỏ",$G$23,$G$24) | J36: =H36*IF(F36="Nhỏ",$E$23,$E$24) | K36: =I36+J36 | L36: 0.3 | M36: =C36*L36
A37: TỔNG | B37: =SUM(B32:B36) | C37: =SUM(C32:C36) | D37: =IF(ABS(B37-1)<0.001,"Tỉ lệ OK","Tổng tỉ lệ phải = 100%") | G37: =SUM(G32:G36) | H37: =SUM(H32:H36) | I37: =SUM(I32:I36) | J37: =SUM(J32:J36) | K37: =SUM(K32:K36) | M37: =SUM(M32:M36)
A38: Cấp 4: agent ~5 bước, mỗi bước mang lại context → token vào lớn. Cấp 1: context RAG ~5 đoạn × 500 token.
A40: 5. Kết quả LLM (BaoGia lấy thẳng từ các ô này)
A41: LLM model nhỏ | B41: =SUMIF(F32:F36,"Nhỏ",K32:K36) | C41: USD/tháng | D41: → BaoGia dòng llm (model nhỏ)
A42: LLM model lớn | B42: =SUMIF(F32:F36,"Lớn",K32:K36) | C42: USD/tháng | D42: → BaoGia dòng llm (model lớn)
A43: Số ảnh sinh mỗi tháng | B43: =C36*$B$27 | C43: ảnh
A44: Sinh ảnh | B44: =$B$43*$B$26 | C44: USD/tháng | D44: → BaoGia dòng llm (sinh ảnh)
A45: Token ra/giây giờ cao điểm | B45: =H37*1000000/($B$6*$B$7*3600)*$B$13 | C45: token/s | D45: Nếu tự host: so với throughput 1 GPU để ra số GPU
...
